[2024-02-20T20:11:38.209+0000] {taskinstance.py:1956} INFO - Dependencies all met for dep_context=non-requeueable deps ti=<TaskInstance: api_dag.get_posts manual__2024-02-20T20:11:36.671545+00:00 [queued]>
[2024-02-20T20:11:38.213+0000] {taskinstance.py:1956} INFO - Dependencies all met for dep_context=requeueable deps ti=<TaskInstance: api_dag.get_posts manual__2024-02-20T20:11:36.671545+00:00 [queued]>
[2024-02-20T20:11:38.214+0000] {taskinstance.py:2170} INFO - Starting attempt 1 of 1
[2024-02-20T20:11:38.221+0000] {taskinstance.py:2191} INFO - Executing <Task(SimpleHttpOperator): get_posts> on 2024-02-20 20:11:36.671545+00:00
[2024-02-20T20:11:38.225+0000] {standard_task_runner.py:60} INFO - Started process 8955 to run task
[2024-02-20T20:11:38.228+0000] {standard_task_runner.py:87} INFO - Running: ['***', 'tasks', 'run', 'api_dag', 'get_posts', 'manual__2024-02-20T20:11:36.671545+00:00', '--job-id', '10', '--raw', '--subdir', 'DAGS_FOLDER/rest_api.py', '--cfg-path', '/tmp/tmphqjvvgr8']
[2024-02-20T20:11:38.230+0000] {standard_task_runner.py:88} INFO - Job 10: Subtask get_posts
[2024-02-20T20:11:38.261+0000] {task_command.py:423} INFO - Running <TaskInstance: api_dag.get_posts manual__2024-02-20T20:11:36.671545+00:00 [running]> on host 4b7631aaf19c
[2024-02-20T20:11:38.298+0000] {taskinstance.py:2480} INFO - Exporting env vars: AIRFLOW_CTX_DAG_OWNER='***' AIRFLOW_CTX_DAG_ID='api_dag' AIRFLOW_CTX_TASK_ID='get_posts' AIRFLOW_CTX_EXECUTION_DATE='2024-02-20T20:11:36.671545+00:00' AIRFLOW_CTX_TRY_NUMBER='1' AIRFLOW_CTX_DAG_RUN_ID='manual__2024-02-20T20:11:36.671545+00:00'
[2024-02-20T20:11:38.300+0000] {http.py:169} INFO - Calling HTTP method
[2024-02-20T20:11:38.311+0000] {taskinstance.py:2698} ERROR - Task failed with exception
Traceback (most recent call last):
  File "/home/airflow/.local/lib/python3.8/site-packages/airflow/models/taskinstance.py", line 433, in _execute_task
    result = execute_callable(context=context, **execute_callable_kwargs)
  File "/home/airflow/.local/lib/python3.8/site-packages/airflow/providers/http/operators/http.py", line 166, in execute
    return self.execute_sync(context=context)
  File "/home/airflow/.local/lib/python3.8/site-packages/airflow/providers/http/operators/http.py", line 170, in execute_sync
    response = self.hook.run(self.endpoint, self.data, self.headers, self.extra_options)
  File "/home/airflow/.local/lib/python3.8/site-packages/airflow/providers/http/operators/http.py", line 148, in hook
    conn = BaseHook.get_connection(conn_id)
  File "/home/airflow/.local/lib/python3.8/site-packages/airflow/hooks/base.py", line 82, in get_connection
    conn = Connection.get_connection_from_secrets(conn_id)
  File "/home/airflow/.local/lib/python3.8/site-packages/airflow/models/connection.py", line 479, in get_connection_from_secrets
    raise AirflowNotFoundException(f"The conn_id `{conn_id}` isn't defined")
airflow.exceptions.AirflowNotFoundException: The conn_id `api_posts` isn't defined
[2024-02-20T20:11:38.314+0000] {taskinstance.py:1138} INFO - Marking task as FAILED. dag_id=api_dag, task_id=get_posts, execution_date=20240220T201136, start_date=20240220T201138, end_date=20240220T201138
[2024-02-20T20:11:38.320+0000] {standard_task_runner.py:107} ERROR - Failed to execute job 10 for task get_posts (The conn_id `api_posts` isn't defined; 8955)
[2024-02-20T20:11:38.362+0000] {local_task_job_runner.py:234} INFO - Task exited with return code 1
[2024-02-20T20:11:38.373+0000] {taskinstance.py:3280} INFO - 0 downstream tasks scheduled from follow-on schedule check
